Workbook

Sheet Публикации
A1: Канал | B1: Дата публикации | C1: Заголовок | D1: Ссылка | E1: Сегмент | F1: Глава 2 | G1: Возраст, дней | H1: Показы | I1: Открытия | J1: Дочитывания | K1: Лайки | L1: Комментарии | M1: Подписки | N1: CTR | O1: Дочитали, % открывших | P1: Дочитываний на 1000 показов | Q1: Показы к медиане дня | R1: Индекс к медиане канала | S1: Класс | T1: Знаков | U1: Доля реплик | V1: Слов в предложении
A2: Изнанка эпох | B2: 46302.414 | C2: Её выдали за принца в девять лет, а потом король запер его в сундуке | D2: https://dzen.ru/media/id/65573443f14fdc5f5f39818c/6ac582093c3baa483e4f5dd3 | E2: новый формат | G2: 0.71 | H2: 44 | I2: 2 | J2: 2 | K2: 0 | L2: 0 | M2: 0 | N2: =IFERROR(I2/H2,"") -> 0.045454545 | O2: =IFERROR(J2/I2,"") -> 1 | P2: =IFERROR(1000*J2/H2,"") -> 45.454545 | Q2: 0.81 | S2: рано (<36 ч или <1000 показов) | T2: 5098 | U2: 0.06 | V2: 9.2
A3: Изнанка эпох | B3: 46302.314 | C3: Король заставил жену взять свою любовницу во фрейлины | D3: https://dzen.ru/media/id/65573443f14fdc5f5f39818c/6ac5809b3f0d266eeb83dbe5 | E3: новый формат | G3: 0.81 | H3: 65 | I3: 10 | J3: 6 | K3: 1 | L3: 0 | M3: 0 | N3: =IFERROR(I3/H3,"") -> 0.15384615 | O3: =IFERROR(J3/I3,"") -> 0.6 | P3: =IFERROR(1000*J3/H3,"") -> 92.307692 | Q3: 1.19 | S3: рано (<36 ч или <1000 показов) | T3: 4966 | U3: 0.06 | V3: 8.4
A4: Изнанка эпох | B4: 46301.418 | C4: Император Август сослал единственную дочь на остров | D4: https://dzen.ru/media/id/65573443f14fdc5f5f39818c/6ac40ddfaebdc212255c0c1d | E4: новый формат | G4: 1.71 | H4: 3352 | I4: 46 | J4: 28 | K4: 2 | L4: 0 | M4: 1 | N4: =IFERROR(I4/H4,"") -> 0.01372315 | O4: =IFERROR(J4/I4,"") -> 0.60869565 | P4: =IFERROR(1000*J4/H4,"") -> 8.353222 | Q4: 0.91 | R4: 0.79 | S4: середина | T4: 5354 | U4: 0.06 | V4: 9.6
A5: Изнанка эпох | B5: 46301.335 | C5: Её сватали за принца, а выдали за его отца-короля | D5: https://dzen.ru/media/id/65573443f14fdc5f5f39818c/6ac40c95079fc9650ed7781a | E5: новый формат | G5: 1.79 | H5: 4002 | I5: 174 | J5: 116 | K5: 5 | L5: 0 | M5: 1 | N5: =IFERROR(I5/H5,"") -> 0.043478261 | O5: =IFERROR(J5/I5,"") -> 0.66666667 | P5: =IFERROR(1000*J5/H5,"") -> 28.985507 | Q5: 1.09 | R5: 2.75 | S5: хит | T5: 5307 | U5: 0.03 | V5: 8.8
A6: Изнанка эпох | B6: 46300.693 | C6: Пленную служанку Пётр I сделал императрицей | D6: https://dzen.ru/media/id/65573443f14fdc5f5f39818c/6ac3879cc615e32447af4004 | E6: новый формат | G6: 2.43 | H6: 4423 | I6: 74 | J6: 44 | K6: 4 | L6: 0 | M6: 1 | N6: =IFERROR(I6/H6,"") -> 0.016730726 | O6: =IFERROR(J6/I6,"") -> 0.59459459 | P6: =IFERROR(1000*J6/H6,"") -> 9.9479991 | Q6: 1 | R6: 0.94 | S6: середина | T6: 6494 | U6: 0.04 | V6: 9.4
A7: Изнанка эпох | B7: 46300.593 | C7: Женщина-фараон носила бороду, а после смерти её стёрли со стен | D7: https://dzen.ru/media/id/65573443f14fdc5f5f39818c/6ac3851e9a90255ae097f3eb | E7: новый формат | G7: 2.53 | H7: 4446 | I7: 80 | J7: 40 | K7: 6 | L7: 0 | M7: 0 | N7: =IFERROR(I7/H7,"") -> 0.017993702 | O7: =IFERROR(J7/I7,"") -> 0.5 | P7: =IFERROR(1000*J7/H7,"") -> 8.9968511 | Q7: 1 | R7: 0.85 | S7: середина | T7: 6475 | U7: 0.02 | V7: 9.2
A8: Изнанка эпох | B8: 46299.898 | C8: Наложница шестого ранга правила Китаем почти полвека | D8: https://dzen.ru/media/id/65573443f14fdc5f5f39818c/6ac258fe94baec70a6fb7f50 | E8: новый формат | G8: 3.23 | H8: 4389 | I8: 60 | J8: 33 | K8: 3 | L8: 0 | M8: 0 | N8: =IFERROR(I8/H8,"") -> 0.01367054 | O8: =IFERROR(J8/I8,"") -> 0.55 | P8: =IFERROR(1000*J8/H8,"") -> 7.518797 | Q8: 0.99 | R8: 0.71 | S8: середина | T8: 5378 | U8: 0.03 | V8: 8.6
A9: Изнанка эпох | B9: 46299.801 | C9: Её считали некрасивой, а она правила Россией | D9: https://dzen.ru/media/id/65573443f14fdc5f5f39818c/6ac25729c990f33951cb5910 | E9: новый формат | G9: 3.32 | H9: 4472 | I9: 96 | J9: 52 | K9: 1 | L9: 0 | M9: 2 | N9: =IFERROR(I9/H9,"") -> 0.021466905 | O9: =IFERROR(J9/I9,"") -> 0.54166667 | P9: =IFERROR(1000*J9/H9,"") -> 11.627907 | Q9: 1.01 | R9: 1.1 | S9: середина | T9: 5484 | U9: 0.03 | V9: 8.6
A10: Изнанка эпох | B10: 46299.694 | C10: Перикл развёлся с женой ради гетеры и плакал за неё в суде | D10: https://dzen.ru/media/id/65573443f14fdc5f5f39818c/6ac255f563181f69f1e32459 | E10: новый формат | G10: 3.43 | H10: 4415 | I10: 57 | J10: 43 | K10: 5 | L10: 1 | M10: 0 | N10: =IFERROR(I10/H10,"") -> 0.012910532 | O10: =IFERROR(J10/I10,"") -> 0.75438596 | P10: =IFERROR(1000*J10/H10,"") -> 9.7395243 | Q10: 1 | R10: 0.92 | S10: середина | T10: 4829 | U10: 0.03 | V10: 9.8
A11: Изнанка эпох | B11: 46298.722 | C11: Её подарили завоевателю, а индейцы назвали предательницей | D11: https://dzen.ru/media/id/65573443f14fdc5f5f39818c/6ac0d414ce5cf40638e9e25c | E11: новый формат | G11: 4.4 | H11: 8914 | I11: 135 | J11: 67 | K11: 5 | L11: 0 | M11: 0 | N11: =IFERROR(I11/H11,"") -> 0.015144716 | O11: =IFERROR(J11/I11,"") -> 0.4962963 | P11: =IFERROR(1000*J11/H11,"") -> 7.5162665 | Q11: 1.02 | R11: 0.71 | S11: середина | T11: 5261 | U11: 0.03 | V11: 10
A12: Изнанка эпох | B12: 46298.636 | C12: Ради Тютчева она четырнадцать лет жила отверженной | D12: https://dzen.ru/media/id/65573443f14fdc5f5f39818c/6ac0d1afe9930679c3174f52 | E12: новый формат | G12: 4.49 | H12: 8718 | I12: 162 | J12: 118 | K12: 2 | L12: 0 | M12: 0 | N12: =IFERROR(I12/H12,"") -> 0.018582244 | O12: =IFERROR(J12/I12,"") -> 0.72839506 | P12: =IFERROR(1000*J12/H12,"") -> 13.535214 | Q12: 0.99 | R12: 1.28 | S12: середина | T12: 4836 | U12: 0.02 | V12: 8.7
A13: Изнанка эпох | B13: 46298.54 | C13: Нельсон завещал её Англии, но Англия от неё отказалась | D13: https://dzen.ru/media/id/65573443f14fdc5f5f39818c/6ac0d0789a90255ae0360419 | E13: новый формат | G13: 4.58 | H13: 8779 | I13: 107 | J13: 61 | K13: 2 | L13: 0 | M13: 0 | N13: =IFERROR(I13/H13,"") -> 0.012188176 | O13: =IFERROR(J13/I13,"") -> 0.57009346 | P13: =IFERROR(1000*J13/H13,"") -> 6.9483996 | Q13: 1 | R13: 0.66 | S13: провал | T13: 5559 | U13: 0.06 | V13: 8.8
A14: Изнанка эпох | B14: 46297.46 | C14: Лукрецию Борджиа отец трижды выдавал замуж ради политики | D14: https://dzen.ru/media/id/65573443f14fdc5f5f39818c/6abec7421e1eef1b04478f94 | E14: новый формат | G14: 5.66 | H14: 12548 | I14: 337 | J14: 228 | K14: 7 | L14: 1 | M14: 3 | N14: =IFERROR(I14/H14,"") -> 0.02685687 | O14: =IFERROR(J14/I14,"") -> 0.67655786 | P14: =IFERROR(1000*J14/H14,"") -> 18.170226 | Q14: 1 | R14: 1.72 | S14: середина | T14: 5298 | U14: 0.03 | V14: 9.7
A15: Изнанка эпох | B15: 46297.379 | C15: Дочь смотрителя медведей стала императрицей и спасла трон мужа | D15: https://dzen.ru/media/id/65573443f14fdc5f5f39818c/6abec5548063754dd38e9a7d | E15: новый формат | G15: 5.75 | H15: 12947 | I15: 132 | J15: 47 | K15: 8 | L15: 0 | M15: 1 | N15: =IFERROR(I15/H15,"") -> 0.010195412 | O15: =IFERROR(J15/I15,"") -> 0.35606061 | P15: =IFERROR(1000*J15/H15,"") -> 3.6301846 | Q15: 1.03 | R15: 0.34 | S15: провал | T15: 5285 | U15: 0.06 | V15: 8.5
... A43: Изнанка эпох | B43: 46288.85 | C43: Её выдали замуж в ледяном доме | D43: https://dzen.ru/media/id/65573443f14fdc5f5f39818c/6ab408f6f592e84253813218 | E43: новый формат | G43: 14.28 | H43: 32537 | I43: 1062 | J43: 869 | K43: 18 | L43: 2 | M43: 7 | N43: =IFERROR(I43/H43,"") -> 0.032639764 | O43: =IFERROR(J43/I43,"") -> 0.81826742 | P43: =IFERROR(1000*J43/H43,"") -> 26.708055 | Q43: 1.17 | R43: 2.53 | S43: хит | T43: 5786 | U43: 0 | V43: 9.7
A44: Изнанка эпох | B44: 46288.71 | C44: Фаворитку короля заподозрили в колдовстве: история жестокой красавицы Версаля | D44: https://dzen.ru/media/id/65573443f14fdc5f5f39818c/6ab3c1361600bb26c0e3424d | E44: переход | G44: 14.42 | H44: 26720 | I44: 369 | J44: 228 | K44: 15 | L44: 0 | M44: 2 | N44: =IFERROR(I44/H44,"") -> 0.01380988 | O44: =IFERROR(J44/I44,"") -> 0.61788618 | P44: =IFERROR(1000*J44/H44,"") -> 8.5329341 | Q44: 0.96 | S44: вне разбора (старый/переходный формат) | T44: 5531 | U44: 0 | V44: 10.3
A45: Изнанка эпох | B45: 46288.668 | C45: Проба невесты на Руси: что это было и почему правду скрыли | D45: https://dzen.ru/media/id/65573443f14fdc5f5f39818c/6ab3b9ba9679235655a85920 | E45: переход (статьи пользователя) | G45: 14.46 | H45: 29085 | I45: 2558 | J45: 676 | K45: 25 | L45: 0 | M45: 7 | N45: =IFERROR(I45/H45,"") -> 0.087949115 | O45: =IFERROR(J45/I45,"") -> 0.26426896 | P45: =IFERROR(1000*J45/H45,"") -> 23.242221 | Q45: 1.04 | S45: вне разбора (старый/переходный формат)
A46: Изнанка эпох | B46: 46288.589 | C46: Первая брачная ночь стала последней: что скрыли от невесты | D46: https://dzen.ru/media/id/65573443f14fdc5f5f39818c/6ab3b14e7d98625a2b7d4b03 | E46: переход (статьи пользователя) | G46: 14.54 | H46: 32573 | I46: 1910 | J46: 770 | K46: 14 | L46: 1 | M46: 7 | N46: =IFERROR(I46/H46,"") -> 0.058637522 | O46: =IFERROR(J46/I46,"") -> 0.40314136 | P46: =IFERROR(1000*J46/H46,"") -> 23.63921 | Q46: 1.17 | S46: вне разбора (старый/переходный формат)
A47: Изнанка эпох | B47: 46288.334 | C47: Чем стирали бельё до мыла | D47: https://dzen.ru/media/id/65573443f14fdc5f5f39818c/6ab1508686f4315f5e743cb8 | E47: старый формат | G47: 14.79 | H47: 4346 | I47: 103 | J47: 72 | K47: 3 | L47: 0 | M47: 0 | N47: =IFERROR(I47/H47,"") -> 0.023699954 | O47: =IFERROR(J47/I47,"") -> 0.69902913 | P47: =IFERROR(1000*J47/H47,"") -> 16.566958 | Q47: 0.16 | S47: вне разбора (старый/переходный формат) | T47: 3153 | U47: 0 | V47: 10.3
A48: Изнанка эпох | B48: 46287.376 | C48: Неприятные обязанности придворного брадобрея | D48: https://dzen.ru/media/id/65573443f14fdc5f5f39818c/6ab14ffb3f2fa613c81996b6 | E48: старый формат | G48: 15.75 | H48: 5293 | I48: 122 | J48: 55 | K48: 2 | L48: 0 | M48: 2 | N48: =IFERROR(I48/H48,"") -> 0.02304931 | O48: =IFERROR(J48/I48,"") -> 0.45081967 | P48: =IFERROR(1000*J48/H48,"") -> 10.391083 | Q48: 1 | S48: вне разбора (старый/переходный формат) | T48: 3263 | U48: 0 | V48: 10
A49: Изнанка эпох | B49: 46286.698 | C49: Как спали в общих постелях | D49: https://dzen.ru/media/id/65573443f14fdc5f5f39818c/6ab13341406cec120075022d | E49: старый формат | G49: 16.43 | H49: 28018 | I49: 2198 | J49: 1623 | K49: 37 | L49: 2 | M49: 5 | N49: =IFERROR(I49/H49,"") -> 0.078449568 | O49: =IFERROR(J49/I49,"") -> 0.73839854 | P49: =IFERROR(1000*J49/H49,"") -> 57.927047 | Q49: 1 | S49: вне разбора (старый/переходный формат) | T49: 3875 | U49: 0 | V49: 11.3
A50: Изнанка эпох | B50: 46285.312 | C50: Что носили под сари | D50: https://dzen.ru/media/id/65573443f14fdc5f5f39818c/6aaeee57b4a3026618499acb | E50: старый формат | G50: 17.81 | H50: 28482 | I50: 1315 | J50: 755 | K50: 23 | L50: 0 | M50: 5 | N50: =IFERROR(I50/H50,"") -> 0.046169511 | O50: =IFERROR(J50/I50,"") -> 0.57414449 | P50: =IFERROR(1000*J50/H50,"") -> 26.50797 | Q50: 1 | S50: вне разбора (старый/переходный формат) | T50: 3483 | U50: 0 | V50: 12.1
A51: Изнанка эпох | B51: 46284.334 | C51: Что раньше делали с молочными зубами | D51: https://dzen.ru/media/id/65573443f14fdc5f5f39818c/6aac572753c058258c27ba36 | E51: старый формат | G51: 18.79 | H51: 5632 | I51: 58 | J51: 30 | K51: 0 | L51: 0 | M51: 1 | N51: =IFERROR(I51/H51,"") -> 0.010298295 | O51: =IFERROR(J51/I51,"") -> 0.51724138 | P51: =IFERROR(1000*J51/H51,"") -> 5.3267045 | Q51: 1 | S51: вне разбора (старый/переходный формат)
A52: Изнанка эпох | B52: 46283.293 | C52: Как мылись женщины Древнего Рима | D52: https://dzen.ru/media/id/65573443f14fdc5f5f39818c/6aac56957039736e701f8600 | E52: старый формат | G52: 19.83 | H52: 32999 | I52: 1607 | J52: 1154 | K52: 30 | L52: 1 | M52: 7 | N52: =IFERROR(I52/H52,"") -> 0.048698445 | O52: =IFERROR(J52/I52,"") -> 0.71810828 | P52: =IFERROR(1000*J52/H52,"") -> 34.970757 | Q52: 1 | S52: вне разбора (старый/переходный формат) | T52: 5072 | U52: 0.09 | V52: 9.8
A53: Изнанка эпох | B53: 46282.335 | C53: Как избавлялись от вшей во дворце | D53: https://dzen.ru/media/id/65573443f14fdc5f5f39818c/6aa9a5447defab6a18d12241 | E53: старый формат | G53: 20.79 | H53: 5299 | I53: 146 | J53: 95 | K53: 3 | L53: 0 | M53: 1 | N53: =IFERROR(I53/H53,"") -> 0.027552368 | O53: =IFERROR(J53/I53,"") -> 0.65068493 | P53: =IFERROR(1000*J53/H53,"") -> 17.927911 | Q53: 1 | S53: вне разбора (старый/переходный формат) | T53: 4803 | U53: 0.1 | V53: 9.8
A54: Изнанка эпох | B54: 46281.335 | C54: Кто мыл руки королю | D54: https://dzen.ru/media/id/65573443f14fdc5f5f39818c/6aa9a373ca5b71607b727811 | E54: старый формат | G54: 21.79 | H54: 5759 | I54: 64 | J54: 31 | K54: 0 | L54: 0 | M54: 1 | N54: =IFERROR(I54/H54,"") -> 0.01111304 | O54: =IFERROR(J54/I54,"") -> 0.484375 | P54: =IFERROR(1000*J54/H54,"") -> 5.382879 | Q54: 1 | S54: вне разбора (старый/переходный формат) | T54: 5315 | U54: 0.09 | V54: 10.1
A55: Изнанка эпох | B55: 46280.566 | C55: Что входило в работу банщицы | D55: https://dzen.ru/media/id/65573443f14fdc5f5f39818c/6aa91df7c7e709610d1e1662 | E55: старый формат | G55: 22.56 | H55: 20015 | I55: 656 | J55: 401 | K55: 17 | L55: 0 | M55: 1 | N55: =IFERROR(I55/H55,"") -> 0.032775418 | O55: =IFERROR(J55/I55,"") -> 0.61128049 | P55: =IFERROR(1000*J55/H55,"") -> 20.034974 | Q55: 1 | S55: вне разбора (старый/переходный формат) | T55: 5814 | U55: 0.13 | V55: 10.9
A56: Изнанка эпох | B56: 46263.824 | C56: Что делали японки с бровями | D56: https://dzen.ru/media/id/65573443f14fdc5f5f39818c/6a9304d68e43707747eb4b11 | E56: старый формат | G56: 39.3 | H56: 35 | I56: 2 | J56: 1 | K56: 0 | L56: 0 | M56: 0 | N56: =IFERROR(I56/H56,"") -> 0.057142857 | O56: =IFERROR(J56/I56,"") -> 0.5 | P56: =IFERROR(1000*J56/H56,"") -> 28.571429 | Q56: 1 | S56: вне разбора (старый/переходный формат) | T56: 7580 | U56: 0 | V56: 6.3
A57: Изнанка эпох | B57: 46249.803 | C57: Чем чистили зубы английские королевы | D57: https://dzen.ru/media/id/65573443f14fdc5f5f39818c/6a808728738ff0547323c9ea | E57: старый формат | G57: 53.32 | H57: 24 | I57: 0 | J57: 0 | K57: 0 | L57: 0 | M57: 0 | N57: =IFERROR(I57/H57,"") -> 0 | O57: =IFERROR(J57/I57,"") | P57: =IFERROR(1000*J57/H57,"") -> 0 | Q57: 1 | S57: вне разбора (старый/переходный формат) | T57: 6056 | U57: 0 | V57: 6.7
A58: Изнанка эпох | B58: 46240.658 | C58: Кого брали в кормилицы к наследнику | D58: https://dzen.ru/media/id/65573443f14fdc5f5f39818c/6a747bdbfdaa4d5842f285ab | E58: старый формат | G58: 62.47 | H58: 17 | I58: 0 | J58: 0 | K58: 0 | L58: 0 | M58: 0 | N58: =IFERROR(I58/H58,"") -> 0 | O58: =IFERROR(J58/I58,"") | P58: =IFERROR(1000*J58/H58,"") -> 0 | Q58: 1 | S58: вне разбора (старый/переходный формат) | T58: 6484 | U58: 0 | V58: 6.9
A59: Изнанка эпох | B59: 46236.1 | C59: Как мылись самураи перед боем | D59: https://dzen.ru/media/id/65573443f14fdc5f5f39818c/6a6e728dcfb48d79ad45e7c6 | E59: старый формат | G59: 67.03 | H59: 18 | I59: 0 | J59: 0 | K59: 0 | L59: 0 | M59: 0 | N59: =IFERROR(I59/H59,"") -> 0 | O59: =IFERROR(J59/I59,"") | P59: =IFERROR(1000*J59/H59,"") -> 0 | Q59: 1 | S59: вне разбора (старый/переходный формат) | T59: 6334 | U59: 0 | V59: 7.3
A60: Изнанка эпох | B60: 46235.834 | C60: Что стояло под кроватью королевы | D60: https://dzen.ru/media/id/65573443f14fdc5f5f39818c/6a6e125645104510f9e82375 | E60: старый формат | G60: 67.29 | H60: 14 | I60: 5 | J60: 2 | K60: 1 | L60: 0 | M60: 0 | N60: =IFERROR(I60/H60,"") -> 0.35714286 | O60: =IFERROR(J60/I60,"") -> 0.4 | P60: =IFERROR(1000*J60/H60,"") -> 142.85714 | Q60: 1 | S60: вне разбора (старый/переходный формат) | T60: 6631 | U60: 0 | V60: 7
A61: Изнанка эпох | B61: 46234.794 | C61: Чем пахла Клеопатра | D61: https://dzen.ru/media/id/65573443f14fdc5f5f39818c/6a6ca94c7d5d8652f17c3b74 | E61: старый формат | G61: 68.33 | H61: 12 | I61: 2 | J61: 1 | K61: 1 | L61: 0 | M61: 0 | N61: =IFERROR(I61/H61,"") -> 0.16666667 | O61: =IFERROR(J61/I61,"") -> 0.5 | P61: =IFERROR(1000*J61/H61,"") -> 83.333333 | Q61: 1 | S61: вне разбора (старый/переходный формат) | T61: 8225 | U61: 0 | V61: 7.5
A62: Маменька велела | B62: 46302.632 | C62: Барыня без имения | D62: https://dzen.ru/media/id/6ac2b2c6e271ea3da0f47ca1/6ac57dd137e6ee15c515eb6c | E62: основной | G62: 0.49 | H62: 1 | I62: 1 | J62: 0 | K62: 0 | L62: 0 | M62: 0 | N62: =IFERROR(I62/H62,"") -> 1 | O62: =IFERROR(J62/I62,"") -> 0 | P62: =IFERROR(1000*J62/H62,"") -> 0 | Q62: 0.5 | S62: рано (<36 ч или <1000 показов) | T62: 9324 | U62: 0.38 | V62: 7.9
A63: Маменька велела | B63: 46302.297 | C63: Сломанный веер | D63: https://dzen.ru/media/id/6ac2b2c6e271ea3da0f47ca1/6ac57d313c3baa483e4c0296 | E63: основной | G63: 0.83 | H63: 3 | I63: 1 | J63: 0 | K63: 1 | L63: 0 | M63: 0 | N63: =IFERROR(I63/H63,"") -> 0.33333333 | O63: =IFERROR(J63/I63,"") -> 0 | P63: =IFERROR(1000*J63/H63,"") -> 0 | Q63: 1.5 | S63: рано (<36 ч или <1000 показов) | T63: 9311 | U63: 0.38 | V63: 8
A64: Маменька велела | B64: 46301.418 | C64: Уля. Вторая хозяйка | D64: https://dzen.ru/media/id/6ac2b2c6e271ea3da0f47ca1/6ac40926679f364783adabe2 | E64: основной | G64: 1.71 | H64: 3295 | I64: 65 | J64: 40 | K64: 4 | L64: 0 | M64: 1 | N64: =IFERROR(I64/H64,"") -> 0.019726859 | O64: =IFERROR(J64/I64,"") -> 0.61538462 | P64: =IFERROR(1000*J64/H64,"") -> 12.139605 | Q64: 1.01 | R64: 1.02 | S64: середина | T64: 9138 | U64: 0.39 | V64: 7.9
A65: Маменька велела | B65: 46301.335 | C65: Чужая невеста | D65: https://dzen.ru/media/id/6ac2b2c6e271ea3da0f47ca1/6ac40856608ac6723889135a | E65: основной | G65: 1.79 | H65: 3211 | I65: 85 | J65: 52 | K65: 6 | L65: 0 | M65: 1 | N65: =IFERROR(I65/H65,"") -> 0.026471504 | O65: =IFERROR(J65/I65,"") -> 0.61176471 | P65: =IFERROR(1000*J65/H65,"") -> 16.194332 | Q65: 0.99 | R65: 1.36 | S65: середина | T65: 9266 | U65: 0.42 | V65: 8.1
A66: Маменька велела | B66: 46300.355 | C66: Невеста с чужим медальоном | D66: https://dzen.ru/media/id/6ac2b2c6e271ea3da0f47ca1/6ac2d4d1e271ea3da01a1e9d | E66: основной | G66: 2.77 | H66: 4229 | I66: 61 | J66: 33 | K66: 1 | L66: 0 | M66: 1 | N66: =IFERROR(I66/H66,"") -> 0.014424214 | O66: =IFERROR(J66/I66,"") -> 0.54098361 | P66: =IFERROR(1000*J66/H66,"") -> 7.8032632 | Q66: 1.01 | R66: 0.65 | S66: провал | T66: 9540 | U66: 0.39 | V66: 8.1
A67: Маменька велела | B67: 46300.25 | C67: Купчиха | D67: https://dzen.ru/media/id/6ac2b2c6e271ea3da0f47ca1/6ac2cef9c7f1ba6adbae2b7e | E67: основной | G67: 2.87 | H67: 4188 | I67: 124 | J67: 68 | K67: 5 | L67: 0 | M67: 0 | N67: =IFERROR(I67/H67,"") -> 0.029608405 | O67: =IFERROR(J67/I67,"") -> 0.5483871 | P67: =IFERROR(1000*J67/H67,"") -> 16.236867 | Q67: 1 | R67: 1.36 | S67: хит | T67: 9426 | U67: 0.44 | V67: 8
...

Sheet Каналы
A1: Канал | B1: Статей | C1: Показы | D1: Открытия | E1: Дочитывания | F1: Подписки | G1: Лайки | H1: CTR | I1: Дочитали, % открывших | J1: Дочитываний на 1000 показов | K1: Подписок на 1000 дочитываний | L1: Лайков на 1000 дочитываний
A2: Свои и чужие | B2: =COUNTIFS(Публикации!$A:$A,$A2,Публикации!$E:$E,"основной") -> 22 | C2: =SUMIFS(Публикации!H:H,Публикации!$A:$A,$A2,Публикации!$E:$E,"основной") -> 536798 | D2: =SUMIFS(Публикации!I:I,Публикации!$A:$A,$A2,Публикации!$E:$E,"основной") -> 115153 | E2: =SUMIFS(Публикации!J:J,Публикации!$A:$A,$A2,Публикации!$E:$E,"основной") -> 100272 | F2: =SUMIFS(Публикации!M:M,Публикации!$A:$A,$A2,Публикации!$E:$E,"основной") -> 291 | G2: =SUMIFS(Публикации!K:K,Публикации!$A:$A,$A2,Публикации!$E:$E,"основной") -> 4266 | H2: =IFERROR(D2/C2,"") -> 0.21451831 | I2: =IFERROR(E2/D2,"") -> 0.87077193 | J2: =IFERROR(1000*E2/C2,"") -> 186.79652 | K2: =IFERROR(1000*F2/E2,"") -> 2.9021063 | L2: =IFERROR(1000*G2/E2,"") -> 42.54428
A3: Общая кухня | B3: =COUNTIFS(Публикации!$A:$A,$A3,Публикации!$E:$E,"основной") -> 14 | C3: =SUMIFS(Публикации!H:H,Публикации!$A:$A,$A3,Публикации!$E:$E,"основной") -> 80933 | D3: =SUMIFS(Публикации!I:I,Публикации!$A:$A,$A3,Публикации!$E:$E,"основной") -> 3707 | E3: =SUMIFS(Публикации!J:J,Публикации!$A:$A,$A3,Публикации!$E:$E,"основной") -> 2709 | F3: =SUMIFS(Публикации!M:M,Публикации!$A:$A,$A3,Публикации!$E:$E,"основной") -> 20 | G3: =SUMIFS(Публикации!K:K,Публикации!$A:$A,$A3,Публикации!$E:$E,"основной") -> 91 | H3: =IFERROR(D3/C3,"") -> 0.045803319 | I3: =IFERROR(E3/D3,"") -> 0.73077961 | J3: =IFERROR(1000*E3/C3,"") -> 33.472131 | K3: =IFERROR(1000*F3/E3,"") -> 7.3827981 | L3: =IFERROR(1000*G3/E3,"") -> 33.591731
A4: Изнанка эпох | B4: =COUNTIFS(Публикации!$A:$A,$A4,Публикации!$E:$E,"новый формат") -> 42 | C4: =SUMIFS(Публикации!H:H,Публикации!$A:$A,$A4,Публикации!$E:$E,"новый формат") -> 691182 | D4: =SUMIFS(Публикации!I:I,Публикации!$A:$A,$A4,Публикации!$E:$E,"новый формат") -> 14638 | E4: =SUMIFS(Публикации!J:J,Публикации!$A:$A,$A4,Публикации!$E:$E,"новый формат") -> 9665 | F4: =SUMIFS(Публикации!M:M,Публикации!$A:$A,$A4,Публикации!$E:$E,"новый формат") -> 99 | G4: =SUMIFS(Публикации!K:K,Публикации!$A:$A,$A4,Публикации!$E:$E,"новый формат") -> 343 | H4: =IFERROR(D4/C4,"") -> 0.021178214 | I4: =IFERROR(E4/D4,"") -> 0.6602678 | J4: =IFERROR(1000*E4/C4,"") -> 13.983292 | K4: =IFERROR(1000*F4/E4,"") -> 10.243145 | L4: =IFERROR(1000*G4/E4,"") -> 35.488877
A5: Маменька велела | B5: =COUNTIFS(Публикации!$A:$A,$A5,Публикации!$E:$E,"основной") -> 8 | C5: =SUMIFS(Публикации!H:H,Публикации!$A:$A,$A5,Публикации!$E:$E,"основной") -> 27529 | D5: =SUMIFS(Публикации!I:I,Публикации!$A:$A,$A5,Публикации!$E:$E,"основной") -> 540 | E5: =SUMIFS(Публикации!J:J,Публикации!$A:$A,$A5,Публикации!$E:$E,"основной") -> 320 | F5: =SUMIFS(Публикации!M:M,Публикации!$A:$A,$A5,Публикации!$E:$E,"основной") -> 8 | G5: =SUMIFS(Публикации!K:K,Публикации!$A:$A,$A5,Публикации!$E:$E,"основной") -> 24 | H5: =IFERROR(D5/C5,"") -> 0.019615678 | I5: =IFERROR(E5/D5,"") -> 0.59259259 | J5: =IFERROR(1000*E5/C5,"") -> 11.624105 | K5: =IFERROR(1000*F5/E5,"") -> 25 | L5: =IFERROR(1000*G5/E5,"") -> 75
A7: Все цифры считаются формулами из листа «Публикации». «Изнанка эпох» только новый формат (с вечера 23.09.2026).

Sheet Признаки
A1: Канал | B1: Признак | C1: Значение | D1: Статей | E1: Медиана CTR | F1: Медиана «дочитали» | G1: Вывод
A2: Изнанка эпох | B2: Пушкин в заголовке | C2: нет | D2: 37 | E2: 0.0165 | F2: 0.608
A3: Изнанка эпох | B3: Пушкин в заголовке | C3: да | D3: 3 | E3: 0.0371 | F3: 0.755
A4: Изнанка эпох | B4: Брак по воле семьи (выдали, сватали, в жёны) | C4: нет | D4: 32 | E4: 0.0165 | F4: 0.596
A5: Изнанка эпох | B5: Брак по воле семьи (выдали, сватали, в жёны) | C5: да | D5: 8 | E5: 0.0297 | F5: 0.693
A6: Изнанка эпох | B6: Русская героиня | C6: нет | D6: 18 | E6: 0.0155 | F6: 0.577
A7: Изнанка эпох | B7: Русская героиня | C7: да | D7: 22 | E7: 0.017 | F7: 0.671
A8: Изнанка эпох | B8: Конструкция «…, а потом…» / «…, а…» / «…, но…» | C8: нет | D8: 29 | E8: 0.0167 | F8: 0.664
A9: Изнанка эпох | B9: Конструкция «…, а потом…» / «…, а…» / «…, но…» | C9: да | D9: 11 | E9: 0.0157 | F9: 0.57
A10: Изнанка эпох | B10: Власть и политика (правила, трон, сослали) | C10: нет | D10: 30 | E10: 0.018 | F10: 0.663
A11: Изнанка эпох | B11: Власть и политика (правила, трон, сослали) | C11: да | D11: 10 | E11: 0.0151 | F11: 0.596
A12: Изнанка эпох | B12: Брак, тело, любовь в заголовке | C12: нет | D12: 18 | E12: 0.0159 | F12: 0.58
A13: Изнанка эпох | B13: Брак, тело, любовь в заголовке | C13: да | D13: 22 | E13: 0.0182 | F13: 0.672
... A17: Свои и чужие | B17: Период | C17: после прорыва | D17: 12 | E17: 0.1879 | F17: 0.872
A18: Свои и чужие | B18: Время публикации (после прорыва) | C18: день и вечер | D18: 4 | E18: 0.1522 | F18: 0.867 | G18: показы к медиане дня: 1.0
A19: Свои и чужие | B19: Время публикации (после прорыва) | C19: утро (до 12:00) | D19: 8 | E19: 0.2149 | F19: 0.872 | G19: показы к медиане дня: 1.13
A21: Посчитано в Python по листу «Публикации»; «Изнанка» только новый формат, статьи старше 1,7 дня. Группы меньше 10 статей = гипотезы.
